[2024-05-29T19:51:50.563+0000] {taskinstance.py:1165} INFO - Dependencies all met for <TaskInstance: 1_dag.store_user manual__2024-05-29T19:51:28.502102+00:00 [queued]>
[2024-05-29T19:51:50.585+0000] {taskinstance.py:1165} INFO - Dependencies all met for <TaskInstance: 1_dag.store_user manual__2024-05-29T19:51:28.502102+00:00 [queued]>
[2024-05-29T19:51:50.586+0000] {taskinstance.py:1362} INFO - 
--------------------------------------------------------------------------------
[2024-05-29T19:51:50.587+0000] {taskinstance.py:1363} INFO - Starting attempt 1 of 1
[2024-05-29T19:51:50.588+0000] {taskinstance.py:1364} INFO - 
--------------------------------------------------------------------------------
[2024-05-29T19:51:50.613+0000] {taskinstance.py:1383} INFO - Executing <Task(PythonOperator): store_user> on 2024-05-29 19:51:28.502102+00:00
[2024-05-29T19:51:50.622+0000] {standard_task_runner.py:55} INFO - Started process 6368 to run task
[2024-05-29T19:51:50.627+0000] {standard_task_runner.py:82} INFO - Running: ['***', 'tasks', 'run', '1_dag', 'store_user', 'manual__2024-05-29T19:51:28.502102+00:00', '--job-id', '41', '--raw', '--subdir', 'DAGS_FOLDER/1_dag.py', '--cfg-path', '/tmp/tmpv1zxkuak']
[2024-05-29T19:51:50.631+0000] {standard_task_runner.py:83} INFO - Job 41: Subtask store_user
[2024-05-29T19:51:50.816+0000] {task_command.py:376} INFO - Running <TaskInstance: 1_dag.store_user manual__2024-05-29T19:51:28.502102+00:00 [running]> on host 4b56679d13b8
[2024-05-29T19:51:50.924+0000] {taskinstance.py:1592} INFO - Exporting the following env vars:
AIRFLOW_CTX_DAG_OWNER=***
AIRFLOW_CTX_DAG_ID=1_dag
AIRFLOW_CTX_TASK_ID=store_user
AIRFLOW_CTX_EXECUTION_DATE=2024-05-29T19:51:28.502102+00:00
AIRFLOW_CTX_TRY_NUMBER=1
AIRFLOW_CTX_DAG_RUN_ID=manual__2024-05-29T19:51:28.502102+00:00
[2024-05-29T19:51:50.926+0000] {postgres.py:129} INFO - Running copy expert: COPY users FROM stdin with DELIMITER as ',' , filename: /tmp/processed_user.csv
[2024-05-29T19:51:50.954+0000] {taskinstance.py:1851} ERROR - Task failed with exception
Traceback (most recent call last):
  File "/home/airflow/.local/lib/python3.7/site-packages/airflow/operators/python.py", line 175, in execute
    return_value = self.execute_callable()
  File "/home/airflow/.local/lib/python3.7/site-packages/airflow/operators/python.py", line 193, in execute_callable
    return self.python_callable(*self.op_args, **self.op_kwargs)
  File "/opt/airflow/dags/1_dag.py", line 29, in _store_user
    filename='/tmp/processed_user.csv')
  File "/home/airflow/.local/lib/python3.7/site-packages/airflow/providers/postgres/hooks/postgres.py", line 135, in copy_expert
    with closing(self.get_conn()) as conn:
  File "/home/airflow/.local/lib/python3.7/site-packages/airflow/providers/postgres/hooks/postgres.py", line 88, in get_conn
    conn = deepcopy(self.connection or self.get_connection(conn_id))
  File "/home/airflow/.local/lib/python3.7/site-packages/airflow/hooks/base.py", line 70, in get_connection
    conn = Connection.get_connection_from_secrets(conn_id)
  File "/home/airflow/.local/lib/python3.7/site-packages/airflow/models/connection.py", line 432, in get_connection_from_secrets
    raise AirflowNotFoundException(f"The conn_id `{conn_id}` isn't defined")
airflow.exceptions.AirflowNotFoundException: The conn_id `postgres_default` isn't defined
[2024-05-29T19:51:50.969+0000] {taskinstance.py:1406} INFO - Marking task as FAILED. dag_id=1_dag, task_id=store_user, execution_date=20240529T195128, start_date=20240529T195150, end_date=20240529T195150
[2024-05-29T19:51:50.989+0000] {standard_task_runner.py:105} ERROR - Failed to execute job 41 for task store_user (The conn_id `postgres_default` isn't defined; 6368)
[2024-05-29T19:51:51.025+0000] {local_task_job.py:164} INFO - Task exited with return code 1
[2024-05-29T19:51:51.055+0000] {local_task_job.py:273} INFO - 0 downstream tasks scheduled from follow-on schedule check
