[2024-05-29T14:53:03.000+0000] {taskinstance.py:1165} INFO - Dependencies all met for <TaskInstance: 1_dag.process_user scheduled__2024-05-28T00:00:00+00:00 [queued]>
[2024-05-29T14:53:04.114+0000] {taskinstance.py:1165} INFO - Dependencies all met for <TaskInstance: 1_dag.process_user scheduled__2024-05-28T00:00:00+00:00 [queued]>
[2024-05-29T14:53:04.118+0000] {taskinstance.py:1362} INFO - 
--------------------------------------------------------------------------------
[2024-05-29T14:53:04.119+0000] {taskinstance.py:1363} INFO - Starting attempt 1 of 1
[2024-05-29T14:53:04.127+0000] {taskinstance.py:1364} INFO - 
--------------------------------------------------------------------------------
[2024-05-29T14:53:04.383+0000] {taskinstance.py:1383} INFO - Executing <Task(PythonOperator): process_user> on 2024-05-28 00:00:00+00:00
[2024-05-29T14:53:04.409+0000] {standard_task_runner.py:55} INFO - Started process 527 to run task
[2024-05-29T14:53:04.440+0000] {standard_task_runner.py:82} INFO - Running: ['***', 'tasks', 'run', '1_dag', 'process_user', 'scheduled__2024-05-28T00:00:00+00:00', '--job-id', '23', '--raw', '--subdir', 'DAGS_FOLDER/1_dag.py', '--cfg-path', '/tmp/tmpu9feoxy9']
[2024-05-29T14:53:04.459+0000] {standard_task_runner.py:83} INFO - Job 23: Subtask process_user
[2024-05-29T14:53:05.327+0000] {task_command.py:376} INFO - Running <TaskInstance: 1_dag.process_user scheduled__2024-05-28T00:00:00+00:00 [running]> on host 4b56679d13b8
[2024-05-29T14:53:07.711+0000] {taskinstance.py:1592} INFO - Exporting the following env vars:
AIRFLOW_CTX_DAG_OWNER=***
AIRFLOW_CTX_DAG_ID=1_dag
AIRFLOW_CTX_TASK_ID=process_user
AIRFLOW_CTX_EXECUTION_DATE=2024-05-28T00:00:00+00:00
AIRFLOW_CTX_TRY_NUMBER=1
AIRFLOW_CTX_DAG_RUN_ID=scheduled__2024-05-28T00:00:00+00:00
[2024-05-29T14:53:07.919+0000] {taskinstance.py:1851} ERROR - Task failed with exception
Traceback (most recent call last):
  File "/home/airflow/.local/lib/python3.7/site-packages/airflow/operators/python.py", line 175, in execute
    return_value = self.execute_callable()
  File "/home/airflow/.local/lib/python3.7/site-packages/airflow/operators/python.py", line 193, in execute_callable
    return self.python_callable(*self.op_args, **self.op_kwargs)
  File "/opt/airflow/dags/1_dag.py", line 13, in _process_user
    user = user ['results'][0]
TypeError: 'NoneType' object is not subscriptable
[2024-05-29T14:53:08.453+0000] {taskinstance.py:1406} INFO - Marking task as FAILED. dag_id=1_dag, task_id=process_user, execution_date=20240528T000000, start_date=20240529T145303, end_date=20240529T145308
[2024-05-29T14:53:08.828+0000] {standard_task_runner.py:105} ERROR - Failed to execute job 23 for task process_user ('NoneType' object is not subscriptable; 527)
[2024-05-29T14:53:09.045+0000] {local_task_job.py:164} INFO - Task exited with return code 1
[2024-05-29T14:53:09.317+0000] {local_task_job.py:273} INFO - 0 downstream tasks scheduled from follow-on schedule check
